<mujoco model="brom_bdx">
  <option iterations="1" ls_iterations="5">
    <flag eulerdamp="disable"/>
  </option>

  <!-- <compiler angle="radian" meshdir="assets" eulerseq="zyx" autolimits="true"/> -->
  <compiler angle="radian" meshdir="assets" eulerseq="zyx"/>

  <default>
    <!-- <joint limited="true" damping="1.0" armature="0.05" frictionloss="0.03"/> -->
    <joint damping="1.0" armature="0.05" frictionloss="0.03"/>
    <!-- <geom condim="4" contype="1" conaffinity="15" friction="0.9 0.2 0.2" solref="0.001 2"/> -->
        <geom contype="0" conaffinity="0"/>
    <!-- <motor ctrllimited="true"/> -->
    <equality solref="0.001 2"/>
    <!-- <default>
      <geom material="visualgeom" condim="1" contype="0" conaffinity="0"/>
    </default> -->
    <!-- <position kp="17.8" kv="0.0" forcerange="-20 20"/> -->
  </default>

  <asset>
    <mesh name="body" file="body.stl" scale="0.001 0.001 0.001"/>
    <mesh name="left_foot" file="left_foot.stl" scale="0.001 0.001 0.001"/>
    <mesh name="left_lower_leg" file="left_lower_leg.stl" scale="0.001 0.001 0.001"/>
    <mesh name="left_upper_leg" file="left_upper_leg.stl" scale="0.001 0.001 0.001"/>
    <mesh name="left_hip" file="left_hip.stl" scale="0.001 0.001 0.001"/>
    <mesh name="left_hip_rotation" file="left_hip_rotation.stl" scale="0.001 0.001 0.001"/>
    <mesh name="right_foot_pad" file="right_foot_pad.stl" scale="0.001 0.001 0.001"/>
    <mesh name="right_foot" file="right_foot.stl" scale="0.001 0.001 0.001"/>
    <mesh name="right_lower_leg" file="right_lower_leg.stl" scale="0.001 0.001 0.001"/>
    <mesh name="right_upper_leg" file="right_upper_leg.stl" scale="0.001 0.001 0.001"/>
    <mesh name="right_hip_rotation" file="right_hip_rotation.stl" scale="0.001 0.001 0.001"/>
    <mesh name="neck_extension" file="neck_extension.stl" scale="0.001 0.001 0.001"/>
    <mesh name="left_foot_pad" file="left_foot_pad.stl" scale="0.001 0.001 0.001"/>
    <mesh name="right_hip" file="right_hip.stl" scale="0.001 0.001 0.001"/>
    <!-- <texture name="texplane" type="2d" builtin="checker" rgb1=".0 .0 .0" rgb2=".8 .8 .8" width="100" height="100"/> -->
    <!-- <material name="matplane" reflectance="0." texture="texplane" texrepeat="1 1" texuniform="true"/>
    <material name="visualgeom" rgba="0.5 0.9 0.2 1"/> -->
  </asset>

  <worldbody>
    <camera name="fixed" pos="0 -3.0 0.9640271041417434" xyaxes="1 0 0 0 0 1"/>
    <camera name="track" mode="trackcom" pos="0 -3.0 0.9640271041417434" xyaxes="1 0 0 0 0 1"/>
    <body name="root" pos="0 0 0.38" quat="1 0 0 0">
      <freejoint name="root"/>
      <site name="imu" size="0.01" pos="0 0 0"/>
      <geom type="mesh" rgba="0.7 0.7 0.7 1" mesh="body"  density="0" group="1"/>
      <geom type="mesh" rgba="0.7 0.7 0.7 1" mesh="body"/>
      <inertial pos="0.00613 0.00011 -0.01349" quat="0.50583 0.49592 0.49592 0.50583" mass="3.674"
        diaginertia="0.04019 0.03434 0.02103"/>
      <body name="left_hip_rotation" pos="0 0.04661 0.0072">
        <joint name="left_hip_yaw" pos="0 0 0" axis="0 0 -1" range="-0.5 0.29" actuatorfrcrange="-100 100"/>
        <geom name="geom_left_hip_rotation" pos="0 -0.04661 -0.0072" type="mesh" rgba="0.7 0.7 0.7 1"
          mesh="left_hip_rotation"  density="0" group="1"/>
        <geom type="mesh" rgba="0.7 0.7 0.7 1" mesh="left_hip_rotation" pos="0 -0.04661 -0.0072"/>
        <inertial pos="0.00350 0.00790 -0.05200" quat="1.00000 0.06700 -0.01800 0.00290" mass="0.689"
          diaginertia="0.00091 0.00063 0.00048"/>
        <body name="left_hip" pos="0.01127 0.004953 -0.059623">
          <joint name="left_hip_roll" pos="0 0 0" axis="1 0 0" range="-0.628319 0.436332" actuatorfrcrange="-100 100"/>
          <geom name="geom_left_hip" pos="-0.01127 -0.051563 0.052423" quat="1 0 0 0" type="mesh" rgba="0.7 0.7 0.7 1"
            mesh="left_hip"  density="0" group="1"/>
          <geom type="mesh" rgba="0.7 0.7 0.7 1" mesh="left_hip" pos="-0.01127 -0.051563 0.052423" quat="1 0 0 0"/>
          <inertial pos="0.01900 0.03500 -0.00028" quat="0.71000 0.71000 -0.00560 -0.02400" mass="0.049"
            diaginertia="0.00005 0.00005 0.00002"/>
          <body name="left_upper_leg" pos="0.019409 0.081888 0">
            <joint name="left_hip_pitch" pos="0 0 0" axis="0 1 0" range="-2.05949 2.05949" actuatorfrcrange="-100 100"/>
            <geom pos="-0.030679 -0.133451 0.052423" quat="1 0 0 0" type="mesh" rgba="0.7 0.7 0.7 1"
              mesh="left_upper_leg"  density="0" group="1"/>
            <geom type="mesh" rgba="0.7 0.7 0.7 1" mesh="left_upper_leg" pos="-0.030679 -0.133451 0.052423"
              quat="1 0 0 0"/>
            <inertial pos="-0.00410 0.01300 -0.05600" quat="0.71000 0.00940 0.00620 0.71000" mass="2.089"
              diaginertia="0.00870 0.00769 0.00218"/>
            <body name="left_lower_leg" pos="-0.000673 0 -0.118509">
              <joint name="left_knee" pos="0 0 0" axis="0 1 0" range="-2.16 0" actuatorfrcrange="-100 100"/>
              <geom pos="-0.030006 -0.133451 0.170932" quat="1 0 0 0" type="mesh" rgba="0.7 0.7 0.7 1"
                mesh="left_lower_leg"  density="0" group="1"/>
              <geom type="mesh" rgba="0.7 0.7 0.7 1" mesh="left_lower_leg" pos="-0.030006 -0.133451 0.170932"
                quat="1 0 0 0"/>
              <inertial pos="0.00073 -0.02400 -0.09300" quat="0.71000 -0.07600 -0.02600 0.70000" mass="0.62"
                diaginertia="0.00210 0.00182 0.00036"/>
              <body name="left_foot_cuboid" pos="0.010774 -0.009467 -0.136762">
                <joint name="left_ankle" pos="0 0 0" axis="0 1 0" range="-1.23 1.48" actuatorfrcrange="-100 100"/>
                <geom pos="-0.04078 -0.123984 0.307694" quat="1 0 0 0" type="mesh" rgba="0.7 0.7 0.7 1" mesh="left_foot"
                   density="0" group="1"/>
                <geom type="mesh" rgba="0.7 0.7 0.7 1" mesh="left_foot" pos="-0.04078 -0.123984 0.307694" quat="1 0 0 0"/>
                <inertial pos="0.04100 -0.00015 -0.03658" quat="0.56198 0.46073 0.56808 0.39100" mass="0.173"
                  diaginertia="0.00012 0.00010 0.00003"/>
                <body name="left_foot" pos="0 0 0">
                  <geom pos="-0.04078 -0.123984 0.307694" quat="1 0 0 0" type="mesh" rgba="0.7 0.7 0.7 1"
                    mesh="left_foot_pad"  density="0" group="1" name="left_foot_pad" contype="0" conaffinity="1" solimp="0.015 1 0.031" friction="0.8 0.02 0.01"/>
                  <geom type="mesh" rgba="0.7 0.7 0.7 1" mesh="left_foot_pad" pos="-0.04078 -0.123984 0.307694"
                    quat="1 0 0 0"/>
                  <inertial pos="0.02600 -0.01500 -0.07100" quat="0.00000 0.71000 0.00000 0.71000" mass="0.1"
                    diaginertia="0.00010 0.00010 0.00001"/>
                </body>
                <site name="left_foot" size="0.015"
                  pos="0.00049999999999996574962 -0.036224999999999729638 0.01955000000000034488"/>
              </body>
            </body>
          </body>
        </body>
      </body>
      <!-- <body name="neck_extension" pos="0.092558 -0.00375 0.053208">
        <joint name="neck_pitch" pos="0 0 0" axis="0 1 0" range="0 1.32645" actuatorfrcrange="-100 100" />
        <geom pos="-0.092558 0.00375 -0.053208" quat="1 0 0 0" type="mesh" rgba="0.7 0.7 0.7 1" mesh="neck_extension"
       density="0" group="1"  />
        <geom type="mesh" rgba="0.7 0.7 0.7 1" mesh="neck_extension" pos="-0.092558 0.00375 -0.053208" quat="1 0 0 0" />
        <inertial pos="-0.06672 -0.00518 0.02423" quat="-0.01943 0.78418 -0.03285 0.62225" mass="0.251" diaginertia="0.00057
      0.00051 0.00014"/>
      </body> -->
      <body name="right_hip_rotation" pos="-9e-06 -0.046484 0.0072">
        <joint name="right_hip_yaw" pos="0 0 0" axis="0 0 -1" range="-0.29 0.5" actuatorfrcrange="-100 100"/>
        <geom pos="9e-06 0.046484 -0.0072" quat="1 0 0 0" type="mesh" rgba="0.7 0.7 0.7 1" mesh="right_hip_rotation"
           density="0" group="1"/>
        <geom type="mesh" rgba="0.7 0.7 0.7 1" mesh="right_hip_rotation" pos="9e-06 0.046484 -0.0072" quat="1 0 0 0"/>
        <inertial pos="0.00350 -0.00770 -0.05100" quat="1.00000 -0.06500 -0.01900 -0.00310" mass="0.689"
          diaginertia="0.00091 0.00063 0.00048"/>
        <body name="right_hip" pos="0.01127 -0.004952 -0.059623">
          <joint name="right_hip_roll" pos="0 0 0" axis="1 0 0" range="-0.436332 0.628319" actuatorfrcrange="-100 100"/>
          <geom pos="-0.011261 0.051436 0.052423" quat="1 0 0 0" type="mesh" rgba="0.7 0.7 0.7 1" mesh="right_hip"
             density="0" group="1"/>
          <geom type="mesh" rgba="0.7 0.7 0.7 1" mesh="right_hip" pos="-0.011261 0.051436 0.052423" quat="1 0 0 0"/>
          <inertial pos="0.01900 -0.03500 -0.00029" quat="0.71000 0.71000 0.02300 0.00580" mass="0.049"
            diaginertia="0.00005 0.00005 0.00002"/>
          <body name="right_upper_leg" pos="0.01941 -0.081889 0">
            <joint name="right_hip_pitch" pos="0 0 0" axis="0 -1 0" range="-2.05949 2.05949" actuatorfrcrange="-100 100"/>
            <geom pos="-0.030671 0.133325 0.052423" quat="1 0 0 0" type="mesh" rgba="0.7 0.7 0.7 1"
              mesh="right_upper_leg"  density="0" group="1"/>
            <geom type="mesh" rgba="0.7 0.7 0.7 1" mesh="right_upper_leg" pos="-0.030671 0.133325 0.052423"
              quat="1 0 0 0"/>
            <inertial pos="-0.00410 -0.01300 -0.05600" quat="0.71000 0.00620 0.00940 0.71000" mass="2.089"
              diaginertia="0.00895 0.00791 0.00224"/>
            <body name="right_lower_leg" pos="-0.000674 0 -0.11851">
              <joint name="right_knee" pos="0 0 0" axis="0 1 0" range="-2.16 0" actuatorfrcrange="-100 100"/>
              <geom pos="-0.029997 0.133325 0.170933" quat="1 0 0 0" type="mesh" rgba="0.7 0.7 0.7 1"
                mesh="right_lower_leg"  density="0" group="1"/>
              <geom type="mesh" rgba="0.7 0.7 0.7 1" mesh="right_lower_leg" pos="-0.029997 0.133325 0.170933"
                quat="1 0 0 0"/>
              <inertial pos="0.00073 0.02400 -0.09300" quat="0.70000 -0.02600 -0.07600 0.71000" mass="0.62"
                diaginertia="0.00210 0.00182 0.00036"/>
              <body name="right_foot_cuboid" pos="0.010775 0.009467 -0.136761">
                <joint name="right_ankle" pos="0 0 0" axis="0 -1 0" range="-1.48 1.23" actuatorfrcrange="-100 100"/>
                <geom pos="-0.040772 0.123858 0.307694" quat="1 0 0 0" type="mesh" rgba="0.7 0.7 0.7 1"
                  mesh="right_foot"  density="0" group="1"/>
                <geom type="mesh" rgba="0.7 0.7 0.7 1" mesh="right_foot" pos="-0.040772 0.123858 0.307694"
                  quat="1 0 0 0"/>
                <inertial pos="0.04100 0.00015 -0.03658" quat="0.39100 0.56808 0.46073 0.56198" mass="0.173"
                  diaginertia="0.00012 0.00010 0.00003"/>
                <body name="right_foot" pos="0 0 0">
                  <geom pos="-0.040772 0.123858 0.307694" quat="1 0 0 0" type="mesh" rgba="0.7 0.7 0.7 1"
                    mesh="right_foot_pad"  density="0" group="1" name="right_foot_pad" contype="0" conaffinity="1" solimp="0.015 1 0.031" friction="0.8 0.02 0.01"/>
                  <geom type="mesh" rgba="0.7 0.7 0.7 1" mesh="right_foot_pad" pos="-0.040772 0.123858 0.307694"
                    quat="1 0 0 0"/>
                  <inertial pos="0.02600 0.01500 -0.07100" quat="0.71000 0.00000 0.71000 0.00000" mass="0.1"
                    diaginertia="0.00010 0.00010 0.00001"/>
                </body>
                <site name="right_foot" size="0.015"
                  pos="0.0005000000000002155498 -0.036224999999999840661 0.019550000000000664069"/>
              </body>
            </body>
          </body>
        </body>
      </body>
    </body>
  </worldbody>

  <actuator>
    <position name="left_hip_yaw" joint="left_hip_yaw" inheritrange="1" kp="10" kv="0.3" forcerange="-23.7 23.7"/>
    <position name="left_hip_roll" joint="left_hip_roll" inheritrange="1" kp="15" kv="0.6" forcerange="-33.5 33.5"/>
    <position name="left_hip_pitch" joint="left_hip_pitch" inheritrange="1" kp="15" kv="0.6" forcerange="-33.5 33.5"/>
    <position name="left_knee" joint="left_knee" inheritrange="1" kp="15" kv="0.6" forcerange="-33.5 33.5"/>
    <position name="left_ankle" joint="left_ankle" inheritrange="1" kp="10" kv="0.3" forcerange="-23.7 23.7"/>
    <!-- <position name="neck_pitch"      joint="neck_pitch"      inheritrange="1" kp="10" kv="0.3" forcerange="-23.7 23.7"/> -->
    <position name="right_hip_yaw" joint="right_hip_yaw" inheritrange="1" kp="10" kv="0.3" forcerange="-23.7 23.7"/>
    <position name="right_hip_roll" joint="right_hip_roll" inheritrange="1" kp="15" kv="0.6" forcerange="-33.5 33.5"/>
    <position name="right_hip_pitch" joint="right_hip_pitch" inheritrange="1" kp="15" kv="0.6" forcerange="-33.5 33.5"/>
    <position name="right_knee" joint="right_knee" inheritrange="1" kp="15" kv="0.6" forcerange="-33.5 33.5"/>
    <position name="right_ankle" joint="right_ankle" inheritrange="1" kp="10" kv="0.3" forcerange="-23.7 23.7"/>
  </actuator>

  <sensor>
    <gyro site="imu" name="gyro"/>
    <velocimeter site="imu" name="local_linvel"/>
    <accelerometer site="imu" name="accelerometer"/>
    <framepos objtype="site" objname="imu" name="position"/>
    <framezaxis objtype="site" objname="imu" name="upvector"/>
    <framexaxis objtype="site" objname="imu" name="forwardvector"/>
    <framelinvel objtype="site" objname="imu" name="global_linvel"/>
    <frameangvel objtype="site" objname="imu" name="global_angvel"/>
    <framequat objtype="site" objname="imu" name="orientation"/>
    <framelinvel objtype="site" objname="right_foot" name="right_foot_global_linvel"/>
    <framelinvel objtype="site" objname="left_foot" name="left_foot_global_linvel"/>
  </sensor>
  <contact>
    <exclude body1="left_hip_rotation" body2="root"/>
    <exclude body1="left_hip" body2="root"/>
    <exclude body1="right_hip_rotation" body2="root"/>
    <exclude body1="right_hip" body2="root"/>
  </contact>
</mujoco>